Workbook

Sheet Resumo
A1: Previdência privada - resumo
A2: Coleta de 24/09/2026 12:36
A4: Plataforma | B4: Renda Fixa | C4: Multimercado | D4: Ações | E4: Cambial | F4: Internacional | G4: Previdência | H4: Outros | I4: Total | J4: Com CNPJ | K4: Gestoras distintas
A5: XP Investimentos | B5: =COUNTIFS(Consolidado!$A$2:$A$486,$A5,Consolidado!$G$2:$G$486,B$4) | C5: =COUNTIFS(Consolidado!$A$2:$A$486,$A5,Consolidado!$G$2:$G$486,C$4) | D5: =COUNTIFS(Consolidado!$A$2:$A$486,$A5,Consolidado!$G$2:$G$486,D$4) | E5: =COUNTIFS(Consolidado!$A$2:$A$486,$A5,Consolidado!$G$2:$G$486,E$4) | F5: =COUNTIFS(Consolidado!$A$2:$A$486,$A5,Consolidado!$G$2:$G$486,F$4) | G5: =COUNTIFS(Consolidado!$A$2:$A$486,$A5,Consolidado!$G$2:$G$486,G$4) | H5: =COUNTIFS(Consolidado!$A$2:$A$486,$A5,Consolidado!$G$2:$G$486,H$4) | I5: =COUNTIF(Consolidado!$A$2:$A$486,$A5) | J5: =COUNTIFS(Consolidado!$A$2:$A$486,$A5,Consolidado!$C$2:$C$486,"<>") | K5: 70
A6: BTG Pactual | B6: =COUNTIFS(Consolidado!$A$2:$A$486,$A6,Consolidado!$G$2:$G$486,B$4) | C6: =COUNTIFS(Consolidado!$A$2:$A$486,$A6,Consolidado!$G$2:$G$486,C$4) | D6: =COUNTIFS(Consolidado!$A$2:$A$486,$A6,Consolidado!$G$2:$G$486,D$4) | E6: =COUNTIFS(Consolidado!$A$2:$A$486,$A6,Consolidado!$G$2:$G$486,E$4) | F6: =COUNTIFS(Consolidado!$A$2:$A$486,$A6,Consolidado!$G$2:$G$486,F$4) | G6: =COUNTIFS(Consolidado!$A$2:$A$486,$A6,Consolidado!$G$2:$G$486,G$4) | H6: =COUNTIFS(Consolidado!$A$2:$A$486,$A6,Consolidado!$G$2:$G$486,H$4) | I6: =COUNTIF(Consolidado!$A$2:$A$486,$A6) | J6: =COUNTIFS(Consolidado!$A$2:$A$486,$A6,Consolidado!$C$2:$C$486,"<>") | K6: 89
A7: Itaú Private | B7: =COUNTIFS(Consolidado!$A$2:$A$486,$A7,Consolidado!$G$2:$G$486,B$4) | C7: =COUNTIFS(Consolidado!$A$2:$A$486,$A7,Consolidado!$G$2:$G$486,C$4) | D7: =COUNTIFS(Consolidado!$A$2:$A$486,$A7,Consolidado!$G$2:$G$486,D$4) | E7: =COUNTIFS(Consolidado!$A$2:$A$486,$A7,Consolidado!$G$2:$G$486,E$4) | F7: =COUNTIFS(Consolidado!$A$2:$A$486,$A7,Consolidado!$G$2:$G$486,F$4) | G7: =COUNTIFS(Consolidado!$A$2:$A$486,$A7,Consolidado!$G$2:$G$486,G$4) | H7: =COUNTIFS(Consolidado!$A$2:$A$486,$A7,Consolidado!$G$2:$G$486,H$4) | I7: =COUNTIF(Consolidado!$A$2:$A$486,$A7) | J7: =COUNTIFS(Consolidado!$A$2:$A$486,$A7,Consolidado!$C$2:$C$486,"<>") | K7: 3
A9: Como ler esta planilha:
A10: As contagens por classe e os totais são fórmulas sobre a aba Consolidado (o catálogo);
A11: "Gestoras distintas" é um valor da coleta, não uma fórmula: contar valores únicos exigiria
A12: função de matriz, que nem todo leitor de planilha avalia da mesma forma.
A13: Uma plataforma com poucos fundos pode ser fonte parcial, não prateleira enxuta - confira a aba Coleta.

Sheet Consolidado
A1: Plataforma | B1: Fundo | C1: CNPJ | D1: Gestora | E1: CNPJ da gestora | F1: Administrador | G1: Classe | H1: Categoria na origem | I1: Aplicação mínima (R$) | J1: Taxa adm (%) | K1: Taxa perf (%) | L1: Benchmark | M1: Cotização resgate (D+) | N1: Líquidação resgate (D+) | O1: Carência (dias) | P1: Tributação | Q1: Fechado p/ captação | R1: Fontes | S1: Nº de fontes | T1: Open Finance | U1: Prateleira (site) | V1: Área logada | W1: Link
A2: XP Investimentos | B2: A1 Hedge Prev Xp Seg Prev Ficfim Rl | C2: 44.409.267/0001-02 | D2: XP VIDA E PREVIDÊNCIA S.A. | E2: 29.408.732/0001-05 | F2: XP Investimentos | G2: Multimercado | H2: Macro Alta Vol | I2: 100 | J2: 2.1 | M2: 22 | N2: 2 | Q2: Não | R2: Site (navegador) | S2: 1 | T2: Não | U2: Sim | V2: Não
A3: XP Investimentos | B3: A1 High Grade Prev XP Seg FIC FIRF CP RL | C3: 63.573.988/0001-06 | D3: ASSET1 INVESTIMENTOS S/A | E3: 35.185.577/0001-08 | F3: Intrag DTVM | G3: Renda Fixa | H3: Crédito Liquidez | I3: 100 | J3: 0.85 | M3: 0 | N3: 2 | Q3: Não | R3: Site (navegador) | S3: 1 | T3: Não | U3: Sim | V3: Não
A4: XP Investimentos | B4: A1 Renda Fixa Ativa Xp Seguros Firf | C4: 52.955.280/0001-95 | D4: ASSET1 INVESTIMENTOS S/A | E4: 35.185.577/0001-08 | F4: XP Investimentos | G4: Multimercado | H4: Renda Fixa Ativo | I4: 100 | J4: 0.9 | M4: 0 | N4: 1 | Q4: Não | R4: Site (navegador) | S4: 1 | T4: Não | U4: Sim | V4: Não
A5: XP Investimentos | B5: ARX Income 100 XP Seg Prev FIC FIA | C5: 34.461.754/0001-60 | D5: XP VIDA E PREVIDÊNCIA S.A. | E5: 29.408.732/0001-05 | F5: BNY Mellon DTVM | G5: Ações | H5: Renda Variável Dividendos | I5: 100 | J5: 2 | M5: 6 | N5: 2 | Q5: Não | R5: Site (navegador) | S5: 1 | T5: Não | U5: Sim | V5: Não
A6: XP Investimentos | B6: AZ Quest Inflação Ativo Prev FIE FIRF | C6: 34.442.059/0001-51 | D6: AZ Quest Prev Ltda. | E6: 59.312.965/0001-62 | F6: BNY Mellon DTVM | G6: Renda Fixa | H6: Renda Fixa Inflação | I6: 500 | J6: 1.1 | M6: 0 | N6: 1 | Q6: Sim | R6: Site (navegador) | S6: 1 | T6: Não | U6: Sim | V6: Não
A7: XP Investimentos | B7: AZ Quest Luce Advisory Prev XP Seg FICFIRF CP | C7: 32.847.001/0001-62 | D7: XP VIDA E PREVIDÊNCIA S.A. | E7: 29.408.732/0001-05 | F7: XPI Administradora - Modal | G7: Renda Fixa | H7: Crédito Liquidez | I7: 100 | J7: 1 | M7: 1 | N7: 2 | Q7: Não | R7: Site (navegador) | S7: 1 | T7: Não | U7: Sim | V7: Não
A8: XP Investimentos | B8: Absolute Atenas Xp Seg Prev Fie I Fic Firf Cp Rl | C8: 62.213.987/0001-80 | D8: ABSOLUTE CRÉDITO GESTÃO DE INVESTIMENTOS LTDA. | E8: 47.243.769/0001-02 | F8: BTG Pactual DTVM | G8: Renda Fixa | H8: Crédito Liquidez | I8: 100 | J8: 0.98 | M8: 6 | N8: 2 | Q8: Não | R8: Site (navegador) | S8: 1 | T8: Não | U8: Sim | V8: Não
A9: XP Investimentos | B9: Absolute Delfos Xp Seg Prev Fie I Fic Rf Cp Rl | C9: 61.904.092/0001-29 | D9: ABSOLUTE CRÉDITO GESTÃO DE INVESTIMENTOS LTDA. | E9: 47.243.769/0001-02 | F9: Intrag DTVM | G9: Renda Fixa | H9: Crédito High Grade | I9: 100 | J9: 0.88 | M9: 20 | N9: 2 | Q9: Não | R9: Site (navegador) | S9: 1 | T9: Não | U9: Sim | V9: Não
A10: XP Investimentos | B10: Absolute Endurance XP Seg FICFIA Prev | C10: 37.355.605/0001-05 | D10: ABSOLUTE GESTAO DE INVESTIMENTOS LTDA | E10: 17.285.755/0001-82 | F10: BNY Mellon DTVM | G10: Ações | H10: Renda Variável Long Only | I10: 100 | J10: 2 | M10: 21 | N10: 2 | Q10: Não | R10: Site (navegador) | S10: 1 | T10: Não | U10: Sim | V10: Não
A11: XP Investimentos | B11: Absolute Pace Xp Seg Prev Fif Em Ações Rl | C11: 61.201.512/0001-00 | D11: ABSOLUTE GESTAO DE INVESTIMENTOS LTDA | E11: 17.285.755/0001-82 | F11: BTG Pactual DTVM | G11: Ações | H11: Renda Variável Long Biased | I11: 100 | J11: 2 | M11: 22 | N11: 2 | Q11: Sim | R11: Site (navegador) | S11: 1 | T11: Não | U11: Sim | V11: Não
A12: XP Investimentos | B12: Absolute Vertex XP Seg Prev FIC FIM | C12: 40.882.496/0001-99 | D12: XP VIDA E PREVIDÊNCIA S.A. | E12: 29.408.732/0001-05 | F12: XPI Administradora - Modal | G12: Multimercado | H12: Macro Alta Vol | I12: 100 | J12: 2 | M12: 21 | N12: 1 | Q12: Não | R12: Site (navegador) | S12: 1 | T12: Não | U12: Sim | V12: Não
A13: XP Investimentos | B13: Ace Capital Prev Iq Xp Seg Fic Fim | C13: 37.541.379/0001-57 | D13: ACE CAPITAL GESTORA DE RECURSOS LTDA. | E13: 33.411.393/0001-85 | F13: Intrag DTVM | G13: Multimercado | H13: Macro Média Vol | I13: 100 | J13: 2 | M13: 6 | N13: 1 | Q13: Não | R13: Site (navegador) | S13: 1 | T13: Não | U13: Sim | V13: Não
... A39: XP Investimentos | B39: Capitânia Reit Prev Adv XP Seg FIE I FIC FIM CP | C39: 35.955.948/0001-85 | D39: CAPITANIA PREV S.A. | E39: 41.777.833/0001-40 | F39: BNY Mellon DTVM | G39: Multimercado | H39: Crédito Híbrido | I39: 100 | J39: 1.25 | M39: 59 | N39: 1 | Q39: Não | R39: Site (navegador) | S39: 1 | T39: Não | U39: Sim | V39: Não
A40: XP Investimentos | B40: Claritas Total Return XP Seg Prev FIE FIC FIM | C40: 37.396.828/0001-10 | D40: Claritas Investimentos (OLD) | F40: BNY Mellon DTVM | G40: Multimercado | H40: Macro Alta Vol | I40: 100 | J40: 2 | M40: 22 | N40: 2 | Q40: Sim | R40: Site (navegador) | S40: 1 | T40: Não | U40: Sim | V40: Não
A41: XP Investimentos | B41: Constellation XP Seg 100 Prev FIC FIM | C41: 35.651.477/0001-11 | D41: CONSTELLATION INVESTIMENTOS E PARTICIPAÇÕES LTDA | E41: 06.182.127/0001-55 | F41: XP Investimentos | G41: Multimercado | H41: Renda Variável Long Only | I41: 1000 | J41: 2 | M41: 40 | N41: 2 | Q41: Não | R41: Site (navegador) | S41: 1 | T41: Não | U41: Sim | V41: Não
A42: XP Investimentos | B42: DNA Energy Prev XP Seg FIM | C42: 35.420.731/0001-70 | D42: XP ADVISORY GESTAO DE RECURSOS LTDA | E42: 15.289.957/0001-77 | F42: XP Investimentos | G42: Multimercado | H42: Multiestratégia | I42: 100 | J42: 0.8 | M42: 6 | N42: 3 | Q42: Não | R42: Site (navegador) | S42: 1 | T42: Não | U42: Sim | V42: Não
A43: XP Investimentos | B43: Dahlia 100 Advisory XP Seg Prev FIC FIM | C43: 36.327.214/0001-14 | D43: DAHLIA CAPITAL GESTÃO DE RECURSOS LTDA. | E43: 09.551.766/0001-39 | F43: BNY Mellon DTVM | G43: Multimercado | H43: Renda Variável Long Only | I43: 100 | J43: 2 | M43: 10 | N43: 2 | Q43: Não | R43: Site (navegador) | S43: 1 | T43: Não | U43: Sim | V43: Não
A44: XP Investimentos | B44: Dahlia 70 Advisory Xp Seg Ii Prev Fic Fim | C44: 43.761.805/0001-60 | D44: XP VIDA E PREVIDÊNCIA S.A. | E44: 29.408.732/0001-05 | F44: XPI Administradora - Modal | G44: Multimercado | H44: Renda Variável Long Only | I44: 100 | J44: 1.5 | M44: 7 | N44: 2 | Q44: Não | R44: Site (navegador) | S44: 1 | T44: Não | U44: Sim | V44: Não
A45: XP Investimentos | B45: Dahlia Global 50 Advisory XP Seg Prev FIC FIM | C45: 37.645.515/0001-59 | D45: DAHLIA CAPITAL GESTÃO DE RECURSOS LTDA. | E45: 09.551.766/0001-39 | F45: BNY Mellon DTVM | G45: Multimercado | H45: Internacional Multimercado Não Hedgeado | I45: 100 | J45: 1.25 | M45: 7 | N45: 2 | Q45: Não | R45: Site (navegador) | S45: 1 | T45: Não | U45: Sim | V45: Não
A46: XP Investimentos | B46: Daycoval Classic Xp Seg Prev Fif Rf Cp Rl | C46: 61.941.773/0001-67 | D46: DAYCOVAL ASSET MANAGEMENT ADMINISTRACAO DE RECURSOS LTDA | E46: 72.027.832/0001-02 | F46: Banco Daycoval | G46: Renda Fixa | H46: Crédito Liquidez | I46: 100 | J46: 0.82 | M46: 0 | N46: 1 | Q46: Não | R46: Site (navegador) | S46: 1 | T46: Não | U46: Sim | V46: Não
A47: XP Investimentos | B47: Drys Shelter Prev XP FIRF CP RL | C47: 63.285.329/0001-66 | D47: DRYS CAPITAL LTDA | E47: 08.204.817/0001-93 | F47: BNY Mellon DTVM | G47: Renda Fixa | H47: Crédito Liquidez | I47: 100 | J47: 0.8 | M47: 5 | N47: 1 | Q47: Não | R47: Site (navegador) | S47: 1 | T47: Não | U47: Sim | V47: Não
A48: XP Investimentos | B48: Encore Long Biased 100 Xp Seg Prev Ficfim Rl | C48: 41.866.111/0001-62 | D48: XP VIDA E PREVIDÊNCIA S.A. | E48: 29.408.732/0001-05 | F48: XPI Administradora - Modal | G48: Multimercado | H48: Renda Variável Long Biased | I48: 100 | J48: 2 | M48: 20 | N48: 2 | Q48: Não | R48: Site (navegador) | S48: 1 | T48: Não | U48: Sim | V48: Não
A49: XP Investimentos | B49: Encore Long Biased 70 XP Seg Prev FIC FIM | C49: 41.802.178/0001-33 | D49: XP VIDA E PREVIDÊNCIA S.A. | E49: 29.408.732/0001-05 | F49: XPI Administradora - Modal | G49: Multimercado | H49: Renda Variável Long Biased | I49: 100 | J49: 1.5 | M49: 7 | N49: 2 | Q49: Não | R49: Site (navegador) | S49: 1 | T49: Não | U49: Sim | V49: Não
A50: XP Investimentos | B50: Forpus 100 XP Seg Prev FICFIA | C50: 40.212.923/0001-21 | D50: FORPUS CAPITAL GESTÃO DE RECURSOS LTDA. | E50: 21.018.289/0001-46 | F50: BNY Mellon DTVM | G50: Ações | H50: Renda Variável Long Only | I50: 100 | J50: 2 | M50: 8 | N50: 2 | Q50: Não | R50: Site (navegador) | S50: 1 | T50: Não | U50: Sim | V50: Não
A51: XP Investimentos | B51: Forpus 70 XP Seg Prev FIM | C51: 42.870.699/0001-90 | D51: FORPUS CAPITAL GESTÃO DE RECURSOS LTDA. | E51: 21.018.289/0001-46 | F51: BNY Mellon DTVM | G51: Multimercado | H51: Renda Variável Long Only | I51: 100 | J51: 2 | M51: 7 | N51: 2 | Q51: Não | R51: Site (navegador) | S51: 1 | T51: Não | U51: Sim | V51: Não
A52: XP Investimentos | B52: Franklin Valor e Liquidez 70 XP Seg FIM | C52: 32.319.047/0001-09 | D52: Franklin Templeton Brasil Ltda. | E52: 07.437.241/0001-41 | F52: BNY Mellon DTVM | G52: Multimercado | H52: Renda Variável Long Only | I52: 100 | J52: 2 | M52: 2 | N52: 2 | Q52: Não | R52: Site (navegador) | S52: 1 | T52: Não | U52: Sim | V52: Não
... A113: XP Investimentos | B113: Lis 100 Prev Xp Seguros Ficfim Rl | C113: 47.033.051/0001-83 | D113: XP VIDA E PREVIDÊNCIA S.A. | E113: 29.408.732/0001-05 | F113: XP Investimentos | G113: Multimercado | H113: Renda Variável Small/Mid Caps | I113: 100 | J113: 2 | M113: 30 | N113: 2 | Q113: Não | R113: Site (navegador) | S113: 1 | T113: Não | U113: Sim | V113: Não
A114: XP Investimentos | B114: Lis 70 Xp Seg Prev Ficfim Rl | C114: 43.860.692/0001-50 | D114: XP Vida e Previdência | F114: XP Investimentos | G114: Multimercado | H114: Renda Variável Small/Mid Caps | I114: 100 | J114: 2 | M114: 7 | N114: 2 | Q114: Sim | R114: Site (navegador) | S114: 1 | T114: Não | U114: Sim | V114: Não
A115: XP Investimentos | B115: M Global 40 Xp Seg Prev Fic Fim Rl | C115: 40.682.081/0001-71 | D115: XP ALLOCATION ASSET MANAGEMENT LTDA | E115: 37.918.829/0001-88 | F115: XP Investimentos | G115: Multimercado | H115: Internacional Ações Não Hedgeado | I115: 100 | J115: 0.94 | M115: 3 | N115: 3 | Q115: Não | R115: Site (navegador) | S115: 1 | T115: Não | U115: Sim | V115: Não
A116: XP Investimentos | B116: M8 Capital XP Seg Previdência FIC FIRF CP RL | C116: 61.539.506/0001-68 | D116: M8 PARTNERS GESTORA DE RECURSOS LTDA. | E116: 18.038.439/0001-79 | F116: BTG Pactual DTVM | G116: Renda Fixa | H116: Crédito High Yield | I116: 100 | J116: 1 | M116: 7 | N116: 2 | Q116: Não | R116: Site (navegador) | S116: 1 | T116: Não | U116: Sim | V116: Não
A117: XP Investimentos | B117: MAG Prev XP Seg Advisory FIRF CP | C117: 32.385.140/0001-11 | D117: MONGERAL AEGON INVESTIMENTOS LTDA | E117: 16.500.294/0001-50 | F117: BNY Mellon DTVM | G117: Renda Fixa | H117: Crédito High Grade | I117: 100 | J117: 0.95 | M117: 1 | N117: 1 | Q117: Não | R117: Site (navegador) | S117: 1 | T117: Não | U117: Sim | V117: Não
A118: XP Investimentos | B118: Mag Cash Xp Seg Prev Ficfirf Rl | C118: 58.543.779/0001-71 | D118: MONGERAL AEGON INVESTIMENTOS LTDA | E118: 16.500.294/0001-50 | F118: BNY Mellon DTVM | G118: Renda Fixa | H118: Crédito Liquidez | I118: 100 | J118: 0.8 | M118: 0 | N118: 1 | Q118: Sim | R118: Site (navegador) | S118: 1 | T118: Não | U118: Sim | V118: Não
A119: XP Investimentos | B119: Mag Prev Rf Fic Fim | C119: 45.645.112/0001-38 | D119: XP VIDA E PREVIDÊNCIA S.A. | E119: 29.408.732/0001-05 | F119: XPI Administradora - Modal | G119: Multimercado | H119: Renda Fixa Ativo | I119: 100 | J119: 0.7 | M119: 0 | N119: 1 | Q119: Não | R119: Site (navegador) | S119: 1 | T119: Não | U119: Sim | V119: Não
A120: XP Investimentos | B120: Mantaro LB Prev Advisory XP Seg FIC FIM | C120: 36.327.253/0001-11 | D120: MANTARO CAPITAL LTDA | E120: 43.353.050/0001-65 | F120: BTG Pactual DTVM | G120: Multimercado | H120: Renda Variável Long Biased | I120: 100 | J120: 2 | M120: 15 | N120: 2 | Q120: Não | R120: Site (navegador) | S120: 1 | T120: Não | U120: Sim | V120: Não
A121: XP Investimentos | B121: Mapfre Confianza XP Seg FIC FIF RF RL | C121: 56.385.272/0001-01 | D121: MAPFRE INVESTIMENTOS LTDA. | E121: 04.160.039/0001-27 | F121: BNY Mellon DTVM | G121: Renda Fixa | H121: Crédito Liquidez | I121: 100 | J121: 0.45 | M121: 0 | N121: 0 | Q121: Não | R121: Site (navegador) | S121: 1 | T121: Não | U121: Sim | V121: Não
A122: XP Investimentos | B122: Miles Virtus Advisory XP Seg Prev FIC FIA | C122: 34.475.121/0001-01 | D122: Miles Capital | F122: BNY Mellon DTVM | G122: Ações | H122: Renda Variável Long Only | I122: 100 | J122: 2 | M122: 2 | N122: 2 | Q122: Sim | R122: Site (navegador) | S122: 1 | T122: Não | U122: Sim | V122: Não
A123: XP Investimentos | B123: Moat Prev XP Seg FICFIA | C123: 37.037.432/0001-87 | D123: MOAT CAPITAL GESTÃO DE RECURSOS LTDA | E123: 18.730.786/0001-68 | F123: Intrag DTVM | G123: Ações | H123: Renda Variável Long Only | I123: 100 | J123: 2 | M123: 15 | N123: 2 | Q123: Não | R123: Site (navegador) | S123: 1 | T123: Não | U123: Sim | V123: Não
A124: XP Investimentos | B124: Neo Navitas Prev XP Seg FICFIA | C124: 41.081.187/0001-82 | D124: NEO Investimentos | F124: Intrag DTVM | G124: Ações | H124: Renda Variável Long Only | I124: 100 | J124: 2 | M124: 22 | N124: 2 | Q124: Sim | R124: Site (navegador) | S124: 1 | T124: Não | U124: Sim | V124: Não
A125: XP Investimentos | B125: Novus Bolsa Macro Global Prev Xp Seg Ficfia | C125: 38.035.023/0001-04 | D125: NOVUS CAPITAL GESTORA DE RECURSOS LTDA. | E125: 15.388.425/0001-97 | F125: Intrag DTVM | G125: Ações | H125: Renda Variável Long Biased | I125: 100 | J125: 2 | M125: 21 | N125: 2 | Q125: Sim | R125: Site (navegador) | S125: 1 | T125: Não | U125: Sim | V125: Não
...

Sheet Vitrine varejo
A1: Plataforma | B1: Fundo | C1: CNPJ | D1: Classe oficial (ANBIMA ou CVM) | E1: Categoria na origem | F1: Gestora | G1: Produto | H1: Taxa adm (%) | I1: Aplicação mínima (R$) | J1: Líquidação resgate (D+) | K1: Situação CVM | L1: Fontes
A2: XP Investimentos | B2: XP Icatu Horizonte Prev FIC FIRF | C2: 18.897.562/0001-45 | D2: Previdência RF Duração Livre Grau de Inv | E2: Renda Fixa Ativo | F2: XP VISTA ASSET MANAGEMENT LTDA. | G2: Própria | H2: 0.8 | I2: 500 | J2: 3 | K2: Em Funcionamento Normal | L2: Site (navegador)
A3: XP Investimentos | B3: XP Icatu Horizonte Macro Prev FIM | C3: 18.927.174/0001-60 | D3: Previdência Multimercado Livre | E3: Macro Baixa Vol | F3: XP GESTÃO DE RECURSOS LTDA | G3: Própria | H3: 2 | I3: 500 | J3: 1 | K3: Em Funcionamento Normal | L3: Site (navegador)
A4: XP Investimentos | B4: Trend B26 Prev XP Seg FIC FIRF RL | C4: 24.714.864/0001-33 | D4: Previdência RF Indexados | E4: Renda Fixa Inflação | F4: XP VIDA E PREVIDÊNCIA S.A. | G4: Própria | H4: 0.3 | I4: 100 | J4: 1 | K4: Em Funcionamento Normal | L4: Site (navegador)
A5: XP Investimentos | B5: Trend B35 Prev XP Seg FIC FIRF RL | C5: 27.077.318/0001-27 | D5: Previdência RF Duração Livre Soberano | E5: Renda Fixa Inflação | F5: XP ALLOCATION ASSET MANAGEMENT LTDA | G5: Própria | H5: 0.3 | I5: 100 | J5: 1 | K5: Em Funcionamento Normal | L5: Site (navegador)
A6: XP Investimentos | B6: Leblon 70 XP Seg Prev FIM | C6: 27.793.095/0001-02 | D6: Previdência Multimercado Livre | E6: Renda Variável Long Only | F6: LEBLON EQUITIES GESTAO DE RECURSOS LTDA | G6: Terceiros | H6: 2 | I6: 100 | J6: 2 | K6: Em Funcionamento Normal | L6: Site (navegador)
A7: XP Investimentos | B7: Verde Am Lb 70 Advisory Xp Seg Prev Fic Fim Rl | C7: 30.830.240/0001-84 | D7: Previdência Multimercado Livre | E7: Renda Variável Long Biased | F7: XP VIDA E PREVIDÊNCIA S.A. | G7: Própria | H7: 2.2 | I7: 100 | J7: 3 | K7: Em Funcionamento Normal | L7: Site (navegador)
A8: XP Investimentos | B8: Kadima Xp Seg Prev Fie Fic Fim Rl | C8: 30.898.110/0001-83 | D8: Previdência Multimercado Livre | E8: Quantitativo | F8: XP VIDA E PREVIDÊNCIA S.A. | G8: Própria | H8: 2 | I8: 100 | J8: 1 | K8: Em Funcionamento Normal | L8: Site (navegador)
A9: XP Investimentos | B9: Xp Corporate Light Cp Xp Seg Fic Rf Rl | C9: 30.910.166/0001-06 | D9: Previdência RF Duração Livre Crédito Liv | E9: Crédito High Grade | F9: XP VISTA ASSET MANAGEMENT LTDA. | G9: Própria | H9: 0.5 | I9: 100 | J9: 1 | K9: Em Funcionamento Normal | L9: Site (navegador)
A10: XP Investimentos | B10: Verde Am Scena Advisory Xp Seg Fic Fim Rl | C10: 30.994.931/0001-13 | D10: Previdência Multimercado Livre | E10: Macro Alta Vol | F10: XP VIDA E PREVIDÊNCIA S.A. | G10: Própria | H10: 2 | I10: 100 | J10: 3 | K10: Em Funcionamento Normal | L10: Site (navegador)
A11: XP Investimentos | B11: Adam Xp Seg Prev I Fic Fim Rl | C11: 30.998.045/0001-68 | D11: Previdência Multimercado Livre | E11: Macro Alta Vol | F11: XP VIDA E PREVIDÊNCIA S.A. | G11: Própria | H11: 2 | I11: 100 | J11: 2 | K11: Em Funcionamento Normal | L11: Site (navegador)
A12: XP Investimentos | B12: RPS Prev Absoluto FIC FIM | C12: 31.340.875/0001-66 | D12: Previdência Multimercado Livre | E12: Long Short Direcional | F12: RPS CAPITAL ADMINISTRADORA DE RECURSOS LTDA | G12: Terceiros | H12: 2 | I12: 500 | J12: 3 | K12: Em Funcionamento Normal | L12: Site (navegador)
A13: XP Investimentos | B13: Spx Lancer Xp Seg Prev I Fic Fim Rl | C13: 31.569.954/0001-43 | D13: Previdência Multimercado Livre | E13: Macro Alta Vol | F13: XP VIDA E PREVIDÊNCIA S.A. | G13: Própria | H13: 2 | I13: 100 | J13: 3 | K13: Em Funcionamento Normal | L13: Site (navegador)
... A47: XP Investimentos | B47: JGP Multimercado Prev Advisory XP Seg FICFI | C47: 34.474.500/0001-87 | D47: Previdência Multimercado Livre | E47: Macro Média Vol | F47: JGP GESTÃO DE RECURSOS LTDA | G47: Terceiros | H47: 2 | I47: 100 | J47: 2 | K47: Em Funcionamento Normal | L47: Site (navegador)
A48: XP Investimentos | B48: Miles Virtus Advisory XP Seg Prev FIC FIA | C48: 34.475.121/0001-01 | E48: Renda Variável Long Only | F48: Miles Capital | G48: Terceiros | H48: 2 | I48: 100 | J48: 2 | L48: Site (navegador)
A49: XP Investimentos | B49: XP Advisory Portfolio Private II Prev FIM CP | C49: 34.475.199/0001-26 | D49: Previdência Multimercado Livre | E49: Multiestratégia | F49: XP ADVISORY GESTAO DE RECURSOS LTDA | G49: Própria | H49: 0.55 | I49: 300000 | J49: 2 | K49: Em Funcionamento Normal | L49: Site (navegador)
A50: XP Investimentos | B50: XP Advisory Portfolio Private III Prev FIM CP | C50: 34.475.378/0001-63 | D50: Previdência Multimercado Livre | E50: Multiestratégia | F50: XP ADVISORY GESTAO DE RECURSOS LTDA | G50: Própria | H50: 0.6 | I50: 300000 | J50: 2 | K50: Em Funcionamento Normal | L50: Site (navegador)
A51: XP Investimentos | B51: Vrb Advisory Prev Fundo De Investimento Multimercado | C51: 34.507.447/0001-73 | D51: Previdência Multimercado Livre | E51: Multiestratégia | F51: XP ADVISORY GESTAO DE RECURSOS LTDA | G51: Própria | H51: 1 | I51: 100 | J51: 3 | K51: Em Funcionamento Normal | L51: Site (navegador)
A52: XP Investimentos | B52: Kinea Apolo Advisory Xp Seg Prev Fic Fim Rl | C52: 35.162.484/0001-50 | D52: Previdência Multimercado Livre | E52: Macro Baixa Vol | F52: XP VIDA E PREVIDÊNCIA S.A. | G52: Própria | H52: 0.8 | I52: 100 | J52: 1 | K52: Em Funcionamento Normal | L52: Site (navegador)
A53: XP Investimentos | B53: Selection Multimercado XP Seg FIC FIM | C53: 35.386.842/0001-08 | D53: Previdência Multimercado Livre | E53: Multiestratégia | F53: XP ADVISORY GESTAO DE RECURSOS LTDA | G53: Própria | H53: 0.8 | I53: 100 | J53: 2 | K53: Em Funcionamento Normal | L53: Site (navegador)
A54: XP Investimentos | B54: XP Seg Superprev FIM | C54: 35.420.569/0001-90 | D54: Previdência Multimercado Livre | E54: Multiestratégia | F54: XP VIDA E PREVIDÊNCIA S.A. | G54: Própria | H54: 0.6 | I54: 100 | J54: 2 | K54: Em Funcionamento Normal | L54: Site (navegador)
A55: XP Investimentos | B55: DNA Energy Prev XP Seg FIM | C55: 35.420.731/0001-70 | D55: Previdência Multimercado Livre | E55: Multiestratégia | F55: XP ADVISORY GESTAO DE RECURSOS LTDA | G55: Própria | H55: 0.8 | I55: 100 | J55: 3 | K55: Em Funcionamento Normal | L55: Site (navegador)
A56: XP Investimentos | B56: Constellation XP Seg 100 Prev FIC FIM | C56: 35.651.477/0001-11 | D56: Previdência Multimercado Livre | E56: Renda Variável Long Only | F56: CONSTELLATION INVESTIMENTOS E PARTICIPAÇÕES LTDA | G56: Terceiros | H56: 2 | I56: 1000 | J56: 2 | K56: Em Funcionamento Normal | L56: Site (navegador)
A57: XP Investimentos | B57: JGP Ações 100 Prev XP Seg FIC FIA | C57: 35.704.530/0001-03 | D57: Previdência Ações Ativo | E57: Renda Variável Long Only | F57: JGP GESTÃO DE RECURSOS LTDA | G57: Terceiros | H57: 2 | I57: 100 | J57: 2 | K57: Em Funcionamento Normal | L57: Site (navegador)
A58: XP Investimentos | B58: Xp Long Biased Advisory Xp Seg Fic Fim | C58: 35.744.196/0001-03 | D58: Previdência Multimercado Livre | E58: Renda Variável Long Biased | F58: XP GESTÃO DE RECURSOS LTDA | G58: Própria | H58: 2 | I58: 100 | J58: 2 | K58: Em Funcionamento Normal | L58: Site (navegador)
A59: XP Investimentos | B59: Alaska Black 70 Advisory XP Seg Prev FIC FIM | C59: 35.939.700/0001-20 | D59: Previdência Multimercado Livre | E59: Renda Variável Long Only | F59: ALASKA INVESTIMENTOS LTDA. | G59: Terceiros | H59: 1.5 | I59: 100 | J59: 2 | K59: Em Funcionamento Normal | L59: Site (navegador)
A60: XP Investimentos | B60: Alaska Black 100 Advisory XP Seg Prev FIC FIM | C60: 35.939.857/0001-56 | D60: Previdência Multimercado Livre | E60: Renda Variável Long Only | F60: ALASKA INVESTIMENTOS LTDA. | G60: Terceiros | H60: 1.5 | I60: 100 | J60: 2 | K60: Em Funcionamento Normal | L60: Site (navegador)
... A75: XP Investimentos | B75: Absolute Endurance XP Seg FICFIA Prev | C75: 37.355.605/0001-05 | D75: Previdência Ações Ativo | E75: Renda Variável Long Only | F75: ABSOLUTE GESTAO DE INVESTIMENTOS LTDA | G75: Terceiros | H75: 2 | I75: 100 | J75: 2 | K75: Em Funcionamento Normal | L75: Site (navegador)
A76: XP Investimentos | B76: Claritas Total Return XP Seg Prev FIE FIC FIM | C76: 37.396.828/0001-10 | E76: Macro Alta Vol | F76: Claritas Investimentos (OLD) | G76: Terceiros | H76: 2 | I76: 100 | J76: 2 | L76: Site (navegador)
A77: XP Investimentos | B77: Ace Capital Prev Iq Xp Seg Fic Fim | C77: 37.541.379/0001-57 | D77: Previdência Multimercado Livre | E77: Macro Média Vol | F77: ACE CAPITAL GESTORA DE RECURSOS LTDA. | G77: Terceiros | H77: 2 | I77: 100 | J77: 1 | K77: Em Funcionamento Normal | L77: Site (navegador)
A78: XP Investimentos | B78: RPS Prev Ações XP Seg FICFI | C78: 37.567.399/0001-05 | D78: Previdência Ações Ativo | E78: Renda Variável Long Only | F78: RPS CAPITAL ADMINISTRADORA DE RECURSOS LTDA | G78: Terceiros | H78: 2 | I78: 100 | J78: 2 | K78: Em Funcionamento Normal | L78: Site (navegador)
A79: XP Investimentos | B79: Dahlia Global 50 Advisory XP Seg Prev FIC FIM | C79: 37.645.515/0001-59 | D79: Previdência Multimercado Livre | E79: Internacional Multimercado Não Hedgeado | F79: DAHLIA CAPITAL GESTÃO DE RECURSOS LTDA. | G79: Terceiros | H79: 1.25 | I79: 100 | J79: 2 | K79: Em Funcionamento Normal | L79: Site (navegador)
A80: XP Investimentos | B80: Kinea Prev Atlas XP Seg FIC FIM | C80: 37.728.799/0001-47 | D80: Previdência Multimercado Livre | E80: Macro Alta Vol | F80: XP VIDA E PREVIDÊNCIA S.A. | G80: Própria | H80: 2 | I80: 100 | J80: 1 | K80: Em Funcionamento Normal | L80: Site (navegador)
A81: XP Investimentos | B81: Truxt Valor XP Seguros Prev FICFIA | C81: 37.893.248/0001-39 | D81: Previdência Ações Ativo | E81: Renda Variável Long Only | F81: TRUXT INVESTIMENTOS LTDA. | G81: Terceiros | H81: 3 | I81: 100 | J81: 2 | K81: Em Funcionamento Normal | L81: Site (navegador)
A82: XP Investimentos | B82: Vista Long Biased Xp Seg Prev 1 Ficfim | C82: 37.900.124/0001-33 | D82: Previdência Multimercado Livre | E82: Renda Variável Long Biased | F82: XP GESTÃO DE RECURSOS LTDA | G82: Própria | H82: 2 | I82: 100 | J82: 2 | K82: Em Funcionamento Normal | L82: Site (navegador)
A83: XP Investimentos | B83: XP Seg Superprev 2 FIM | C83: 37.900.216/0001-13 | D83: Previdência Multimercado Livre | E83: Multiestratégia | F83: XP VIDA E PREVIDÊNCIA S.A. | G83: Própria | H83: 0.6 | I83: 100 | J83: 2 | K83: Em Funcionamento Normal | L83: Site (navegador)
A84: XP Investimentos | B84: Novus Bolsa Macro Global Prev Xp Seg Ficfia | C84: 38.035.023/0001-04 | D84: Previdência Ações Ativo | E84: Renda Variável Long Biased | F84: NOVUS CAPITAL GESTORA DE RECURSOS LTDA. | G84: Terceiros | H84: 2 | I84: 100 | J84: 2 | K84: Em Funcionamento Normal | L84: Site (navegador)
A85: XP Investimentos | B85: Oceana Long Biased Advisory XP Seg Prev FIC FIM | C85: 38.236.291/0001-94 | D85: Previdência Multimercado Livre | E85: Renda Variável Long Biased | F85: OCEANA INVESTIMENTOS ADMINISTRADORA DE CARTEIRA DE VALORES MOBILIÁRIOS LTDA | G85: Terceiros | H85: 2 | I85: 100 | J85: 2 | K85: Em Funcionamento Normal | L85: Site (navegador)
A86: XP Investimentos | B86: Oceana Valor Advisory XP Seg Prev FICFIA | C86: 39.958.567/0001-00 | D86: Previdência Ações Ativo | E86: Renda Variável Long Only | F86: XP VIDA E PREVIDÊNCIA S.A. | G86: Própria | H86: 2 | I86: 100 | J86: 2 | K86: Em Funcionamento Normal | L86: Site (navegador)
A87: XP Investimentos | B87: Hashdex 40 Nasdaq Crypto Index Xp Seg Prev Ficfim Rl | C87: 39.992.897/0001-12 | D87: Previdência Multimercado Livre | E87: Alternativo Líquido | F87: XP VIDA E PREVIDÊNCIA S.A. | G87: Própria | H87: 1.5 | I87: 100 | J87: 2 | K87: Em Funcionamento Normal | L87: Site (navegador)
...

Sheet Restritos (auxiliar)
A1: Plataforma | B1: Fundo | C1: CNPJ | D1: Motivo | E1: Classe oficial | F1: Gestora | G1: Na vitrine | H1: Fontes
A2: XP Investimentos | B2: Alaska Black 100 Advisory XP Seg Prev FIC FIM sem pfee | C2: 32.757.743/0001-05 | D2: público-alvo profissional (segundo a casa) | E2: Previdência Multimercado Livre | F2: ALASKA INVESTIMENTOS LTDA. | G2: Sim | H2: Site (navegador)
A3: XP Investimentos | B3: Alaska Black 70 Advisory XP Seg Prev FIC FIM sem pfee | C3: 32.761.323/0001-94 | D3: público-alvo profissional (segundo a casa) | E3: Previdência Multimercado Livre | F3: ALASKA INVESTIMENTOS LTDA. | G3: Sim | H3: Site (navegador)
A4: XP Investimentos | B4: Legacy Capital Prev Advisory XP Seg FIC FIM | C4: 34.287.126/0001-00 | D4: público-alvo profissional (segundo a casa) | E4: Previdência Multimercado Livre | F4: LEGACY CAPITAL GESTORA DE RECURSOS LTDA. | G4: Sim | H4: Site (navegador)
A5: XP Investimentos | B5: Velt Advisory XP Seg Prev FIC FIA | C5: 36.352.636/0001-40 | D5: público-alvo profissional (segundo a casa) | E5: Previdência Ações Ativo | F5: VELT PARTNERS INVESTIMENTOS LTDA | G5: Sim | H5: Site (navegador)
A6: XP Investimentos | B6: Xp Long Biased Ii Seg Fic Fim | C6: 34.430.623/0001-16 | D6: público-alvo profissional (segundo a casa) | E6: Previdência Multimercado Livre | F6: XP VIDA E PREVIDÊNCIA S.A. | G6: Sim | H6: Site (navegador)

Sheet Movimentos
A1: Plataforma | B1: Movimento | C1: Fundo | D1: CNPJ | E1: Na vitrine | F1: Detalhe
A2: BTG Pactual | B2: alteração | C2: Finacap BP Prev 70 FIF MM | D2: 67.671.091/0001-68 | F2: closed_for_investment: True -> False

Sheet XP Investimentos
A1: Plataforma | B1: Fundo | C1: CNPJ | D1: Gestora | E1: CNPJ da gestora | F1: Administrador | G1: Classe | H1: Categoria na origem | I1: Aplicação mínima (R$) | J1: Taxa adm (%) | K1: Taxa perf (%) | L1: Benchmark | M1: Cotização resgate (D+) | N1: Líquidação resgate (D+) | O1: Carência (dias) | P1: Tributação | Q1: Fechado p/ captação | R1: Fontes | S1: Nº de fontes | T1: Open Finance | U1: Prateleira (site) | V1: Área logada | W1: Link
A2: XP Investimentos | B2: A1 Hedge Prev Xp Seg Prev Ficfim Rl | C2: 44.409.267/0001-02 | D2: XP VIDA E PREVIDÊNCIA S.A. | E2: 29.408.732/0001-05 | F2: XP Investimentos | G2: Multimercado | H2: Macro Alta Vol | I2: 100 | J2: 2.1 | M2: 22 | N2: 2 | Q2: Não | R2: Site (navegador) | S2: 1 | T2: Não | U2: Sim | V2: Não
A3: XP Investimentos | B3: A1 High Grade Prev XP Seg FIC FIRF CP RL | C3: 63.573.988/0001-06 | D3: ASSET1 INVESTIMENTOS S/A | E3: 35.185.577/0001-08 | F3: Intrag DTVM | G3: Renda Fixa | H3: Crédito Liquidez | I3: 100 | J3: 0.85 | M3: 0 | N3: 2 | Q3: Não | R3: Site (navegador) | S3: 1 | T3: Não | U3: Sim | V3: Não
A4: XP Investimentos | B4: A1 Renda Fixa Ativa Xp Seguros Firf | C4: 52.955.280/0001-95 | D4: ASSET1 INVESTIMENTOS S/A | E4: 35.185.577/0001-08 | F4: XP Investimentos | G4: Multimercado | H4: Renda Fixa Ativo | I4: 100 | J4: 0.9 | M4: 0 | N4: 1 | Q4: Não | R4: Site (navegador) | S4: 1 | T4: Não | U4: Sim | V4: Não
A5: XP Investimentos | B5: ARX Income 100 XP Seg Prev FIC FIA | C5: 34.461.754/0001-60 | D5: XP VIDA E PREVIDÊNCIA S.A. | E5: 29.408.732/0001-05 | F5: BNY Mellon DTVM | G5: Ações | H5: Renda Variável Dividendos | I5: 100 | J5: 2 | M5: 6 | N5: 2 | Q5: Não | R5: Site (navegador) | S5: 1 | T5: Não | U5: Sim | V5: Não
A6: XP Investimentos | B6: AZ Quest Inflação Ativo Prev FIE FIRF | C6: 34.442.059/0001-51 | D6: AZ Quest Prev Ltda. | E6: 59.312.965/0001-62 | F6: BNY Mellon DTVM | G6: Renda Fixa | H6: Renda Fixa Inflação | I6: 500 | J6: 1.1 | M6: 0 | N6: 1 | Q6: Sim | R6: Site (navegador) | S6: 1 | T6: Não | U6: Sim | V6: Não
A7: XP Investimentos | B7: AZ Quest Luce Advisory Prev XP Seg FICFIRF CP | C7: 32.847.001/0001-62 | D7: XP VIDA E PREVIDÊNCIA S.A. | E7: 29.408.732/0001-05 | F7: XPI Administradora - Modal | G7: Renda Fixa | H7: Crédito Liquidez | I7: 100 | J7: 1 | M7: 1 | N7: 2 | Q7: Não | R7: Site (navegador) | S7: 1 | T7: Não | U7: Sim | V7: Não
A8: XP Investimentos | B8: Absolute Atenas Xp Seg Prev Fie I Fic Firf Cp Rl | C8: 62.213.987/0001-80 | D8: ABSOLUTE CRÉDITO GESTÃO DE INVESTIMENTOS LTDA. | E8: 47.243.769/0001-02 | F8: BTG Pactual DTVM | G8: Renda Fixa | H8: Crédito Liquidez | I8: 100 | J8: 0.98 | M8: 6 | N8: 2 | Q8: Não | R8: Site (navegador) | S8: 1 | T8: Não | U8: Sim | V8: Não
A9: XP Investimentos | B9: Absolute Delfos Xp Seg Prev Fie I Fic Rf Cp Rl | C9: 61.904.092/0001-29 | D9: ABSOLUTE CRÉDITO GESTÃO DE INVESTIMENTOS LTDA. | E9: 47.243.769/0001-02 | F9: Intrag DTVM | G9: Renda Fixa | H9: Crédito High Grade | I9: 100 | J9: 0.88 | M9: 20 | N9: 2 | Q9: Não | R9: Site (navegador) | S9: 1 | T9: Não | U9: Sim | V9: Não
A10: XP Investimentos | B10: Absolute Endurance XP Seg FICFIA Prev | C10: 37.355.605/0001-05 | D10: ABSOLUTE GESTAO DE INVESTIMENTOS LTDA | E10: 17.285.755/0001-82 | F10: BNY Mellon DTVM | G10: Ações | H10: Renda Variável Long Only | I10: 100 | J10: 2 | M10: 21 | N10: 2 | Q10: Não | R10: Site (navegador) | S10: 1 | T10: Não | U10: Sim | V10: Não
A11: XP Investimentos | B11: Absolute Pace Xp Seg Prev Fif Em Ações Rl | C11: 61.201.512/0001-00 | D11: ABSOLUTE GESTAO DE INVESTIMENTOS LTDA | E11: 17.285.755/0001-82 | F11: BTG Pactual DTVM | G11: Ações | H11: Renda Variável Long Biased | I11: 100 | J11: 2 | M11: 22 | N11: 2 | Q11: Sim | R11: Site (navegador) | S11: 1 | T11: Não | U11: Sim | V11: Não
A12: XP Investimentos | B12: Absolute Vertex XP Seg Prev FIC FIM | C12: 40.882.496/0001-99 | D12: XP VIDA E PREVIDÊNCIA S.A. | E12: 29.408.732/0001-05 | F12: XPI Administradora - Modal | G12: Multimercado | H12: Macro Alta Vol | I12: 100 | J12: 2 | M12: 21 | N12: 1 | Q12: Não | R12: Site (navegador) | S12: 1 | T12: Não | U12: Sim | V12: Não
A13: XP Investimentos | B13: Ace Capital Prev Iq Xp Seg Fic Fim | C13: 37.541.379/0001-57 | D13: ACE CAPITAL GESTORA DE RECURSOS LTDA. | E13: 33.411.393/0001-85 | F13: Intrag DTVM | G13: Multimercado | H13: Macro Média Vol | I13: 100 | J13: 2 | M13: 6 | N13: 1 | Q13: Não | R13: Site (navegador) | S13: 1 | T13: Não | U13: Sim | V13: Não
... A39: XP Investimentos | B39: Capitânia Reit Prev Adv XP Seg FIE I FIC FIM CP | C39: 35.955.948/0001-85 | D39: CAPITANIA PREV S.A. | E39: 41.777.833/0001-40 | F39: BNY Mellon DTVM | G39: Multimercado | H39: Crédito Híbrido | I39: 100 | J39: 1.25 | M39: 59 | N39: 1 | Q39: Não | R39: Site (navegador) | S39: 1 | T39: Não | U39: Sim | V39: Não
A40: XP Investimentos | B40: Claritas Total Return XP Seg Prev FIE FIC FIM | C40: 37.396.828/0001-10 | D40: Claritas Investimentos (OLD) | F40: BNY Mellon DTVM | G40: Multimercado | H40: Macro Alta Vol | I40: 100 | J40: 2 | M40: 22 | N40: 2 | Q40: Sim | R40: Site (navegador) | S40: 1 | T40: Não | U40: Sim | V40: Não
A41: XP Investimentos | B41: Constellation XP Seg 100 Prev FIC FIM | C41: 35.651.477/0001-11 | D41: CONSTELLATION INVESTIMENTOS E PARTICIPAÇÕES LTDA | E41: 06.182.127/0001-55 | F41: XP Investimentos | G41: Multimercado | H41: Renda Variável Long Only | I41: 1000 | J41: 2 | M41: 40 | N41: 2 | Q41: Não | R41: Site (navegador) | S41: 1 | T41: Não | U41: Sim | V41: Não
A42: XP Investimentos | B42: DNA Energy Prev XP Seg FIM | C42: 35.420.731/0001-70 | D42: XP ADVISORY GESTAO DE RECURSOS LTDA | E42: 15.289.957/0001-77 | F42: XP Investimentos | G42: Multimercado | H42: Multiestratégia | I42: 100 | J42: 0.8 | M42: 6 | N42: 3 | Q42: Não | R42: Site (navegador) | S42: 1 | T42: Não | U42: Sim | V42: Não
A43: XP Investimentos | B43: Dahlia 100 Advisory XP Seg Prev FIC FIM | C43: 36.327.214/0001-14 | D43: DAHLIA CAPITAL GESTÃO DE RECURSOS LTDA. | E43: 09.551.766/0001-39 | F43: BNY Mellon DTVM | G43: Multimercado | H43: Renda Variável Long Only | I43: 100 | J43: 2 | M43: 10 | N43: 2 | Q43: Não | R43: Site (navegador) | S43: 1 | T43: Não | U43: Sim | V43: Não
A44: XP Investimentos | B44: Dahlia 70 Advisory Xp Seg Ii Prev Fic Fim | C44: 43.761.805/0001-60 | D44: XP VIDA E PREVIDÊNCIA S.A. | E44: 29.408.732/0001-05 | F44: XPI Administradora - Modal | G44: Multimercado | H44: Renda Variável Long Only | I44: 100 | J44: 1.5 | M44: 7 | N44: 2 | Q44: Não | R44: Site (navegador) | S44: 1 | T44: Não | U44: Sim | V44: Não
A45: XP Investimentos | B45: Dahlia Global 50 Advisory XP Seg Prev FIC FIM | C45: 37.645.515/0001-59 | D45: DAHLIA CAPITAL GESTÃO DE RECURSOS LTDA. | E45: 09.551.766/0001-39 | F45: BNY Mellon DTVM | G45: Multimercado | H45: Internacional Multimercado Não Hedgeado | I45: 100 | J45: 1.25 | M45: 7 | N45: 2 | Q45: Não | R45: Site (navegador) | S45: 1 | T45: Não | U45: Sim | V45: Não
A46: XP Investimentos | B46: Daycoval Classic Xp Seg Prev Fif Rf Cp Rl | C46: 61.941.773/0001-67 | D46: DAYCOVAL ASSET MANAGEMENT ADMINISTRACAO DE RECURSOS LTDA | E46: 72.027.832/0001-02 | F46: Banco Daycoval | G46: Renda Fixa | H46: Crédito Liquidez | I46: 100 | J46: 0.82 | M46: 0 | N46: 1 | Q46: Não | R46: Site (navegador) | S46: 1 | T46: Não | U46: Sim | V46: Não
A47: XP Investimentos | B47: Drys Shelter Prev XP FIRF CP RL | C47: 63.285.329/0001-66 | D47: DRYS CAPITAL LTDA | E47: 08.204.817/0001-93 | F47: BNY Mellon DTVM | G47: Renda Fixa | H47: Crédito Liquidez | I47: 100 | J47: 0.8 | M47: 5 | N47: 1 | Q47: Não | R47: Site (navegador) | S47: 1 | T47: Não | U47: Sim | V47: Não
A48: XP Investimentos | B48: Encore Long Biased 100 Xp Seg Prev Ficfim Rl | C48: 41.866.111/0001-62 | D48: XP VIDA E PREVIDÊNCIA S.A. | E48: 29.408.732/0001-05 | F48: XPI Administradora - Modal | G48: Multimercado | H48: Renda Variável Long Biased | I48: 100 | J48: 2 | M48: 20 | N48: 2 | Q48: Não | R48: Site (navegador) | S48: 1 | T48: Não | U48: Sim | V48: Não
A49: XP Investimentos | B49: Encore Long Biased 70 XP Seg Prev FIC FIM | C49: 41.802.178/0001-33 | D49: XP VIDA E PREVIDÊNCIA S.A. | E49: 29.408.732/0001-05 | F49: XPI Administradora - Modal | G49: Multimercado | H49: Renda Variável Long Biased | I49: 100 | J49: 1.5 | M49: 7 | N49: 2 | Q49: Não | R49: Site (navegador) | S49: 1 | T49: Não | U49: Sim | V49: Não
A50: XP Investimentos | B50: Forpus 100 XP Seg Prev FICFIA | C50: 40.212.923/0001-21 | D50: FORPUS CAPITAL GESTÃO DE RECURSOS LTDA. | E50: 21.018.289/0001-46 | F50: BNY Mellon DTVM | G50: Ações | H50: Renda Variável Long Only | I50: 100 | J50: 2 | M50: 8 | N50: 2 | Q50: Não | R50: Site (navegador) | S50: 1 | T50: Não | U50: Sim | V50: Não
A51: XP Investimentos | B51: Forpus 70 XP Seg Prev FIM | C51: 42.870.699/0001-90 | D51: FORPUS CAPITAL GESTÃO DE RECURSOS LTDA. | E51: 21.018.289/0001-46 | F51: BNY Mellon DTVM | G51: Multimercado | H51: Renda Variável Long Only | I51: 100 | J51: 2 | M51: 7 | N51: 2 | Q51: Não | R51: Site (navegador) | S51: 1 | T51: Não | U51: Sim | V51: Não
A52: XP Investimentos | B52: Franklin Valor e Liquidez 70 XP Seg FIM | C52: 32.319.047/0001-09 | D52: Franklin Templeton Brasil Ltda. | E52: 07.437.241/0001-41 | F52: BNY Mellon DTVM | G52: Multimercado | H52: Renda Variável Long Only | I52: 100 | J52: 2 | M52: 2 | N52: 2 | Q52: Não | R52: Site (navegador) | S52: 1 | T52: Não | U52: Sim | V52: Não
... A113: XP Investimentos | B113: Lis 100 Prev Xp Seguros Ficfim Rl | C113: 47.033.051/0001-83 | D113: XP VIDA E PREVIDÊNCIA S.A. | E113: 29.408.732/0001-05 | F113: XP Investimentos | G113: Multimercado | H113: Renda Variável Small/Mid Caps | I113: 100 | J113: 2 | M113: 30 | N113: 2 | Q113: Não | R113: Site (navegador) | S113: 1 | T113: Não | U113: Sim | V113: Não
A114: XP Investimentos | B114: Lis 70 Xp Seg Prev Ficfim Rl | C114: 43.860.692/0001-50 | D114: XP Vida e Previdência | F114: XP Investimentos | G114: Multimercado | H114: Renda Variável Small/Mid Caps | I114: 100 | J114: 2 | M114: 7 | N114: 2 | Q114: Sim | R114: Site (navegador) | S114: 1 | T114: Não | U114: Sim | V114: Não
A115: XP Investimentos | B115: M Global 40 Xp Seg Prev Fic Fim Rl | C115: 40.682.081/0001-71 | D115: XP ALLOCATION ASSET MANAGEMENT LTDA | E115: 37.918.829/0001-88 | F115: XP Investimentos | G115: Multimercado | H115: Internacional Ações Não Hedgeado | I115: 100 | J115: 0.94 | M115: 3 | N115: 3 | Q115: Não | R115: Site (navegador) | S115: 1 | T115: Não | U115: Sim | V115: Não
A116: XP Investimentos | B116: M8 Capital XP Seg Previdência FIC FIRF CP RL | C116: 61.539.506/0001-68 | D116: M8 PARTNERS GESTORA DE RECURSOS LTDA. | E116: 18.038.439/0001-79 | F116: BTG Pactual DTVM | G116: Renda Fixa | H116: Crédito High Yield | I116: 100 | J116: 1 | M116: 7 | N116: 2 | Q116: Não | R116: Site (navegador) | S116: 1 | T116: Não | U116: Sim | V116: Não
A117: XP Investimentos | B117: MAG Prev XP Seg Advisory FIRF CP | C117: 32.385.140/0001-11 | D117: MONGERAL AEGON INVESTIMENTOS LTDA | E117: 16.500.294/0001-50 | F117: BNY Mellon DTVM | G117: Renda Fixa | H117: Crédito High Grade | I117: 100 | J117: 0.95 | M117: 1 | N117: 1 | Q117: Não | R117: Site (navegador) | S117: 1 | T117: Não | U117: Sim | V117: Não
A118: XP Investimentos | B118: Mag Cash Xp Seg Prev Ficfirf Rl | C118: 58.543.779/0001-71 | D118: MONGERAL AEGON INVESTIMENTOS LTDA | E118: 16.500.294/0001-50 | F118: BNY Mellon DTVM | G118: Renda Fixa | H118: Crédito Liquidez | I118: 100 | J118: 0.8 | M118: 0 | N118: 1 | Q118: Sim | R118: Site (navegador) | S118: 1 | T118: Não | U118: Sim | V118: Não
A119: XP Investimentos | B119: Mag Prev Rf Fic Fim | C119: 45.645.112/0001-38 | D119: XP VIDA E PREVIDÊNCIA S.A. | E119: 29.408.732/0001-05 | F119: XPI Administradora - Modal | G119: Multimercado | H119: Renda Fixa Ativo | I119: 100 | J119: 0.7 | M119: 0 | N119: 1 | Q119: Não | R119: Site (navegador) | S119: 1 | T119: Não | U119: Sim | V119: Não
A120: XP Investimentos | B120: Mantaro LB Prev Advisory XP Seg FIC FIM | C120: 36.327.253/0001-11 | D120: MANTARO CAPITAL LTDA | E120: 43.353.050/0001-65 | F120: BTG Pactual DTVM | G120: Multimercado | H120: Renda Variável Long Biased | I120: 100 | J120: 2 | M120: 15 | N120: 2 | Q120: Não | R120: Site (navegador) | S120: 1 | T120: Não | U120: Sim | V120: Não
A121: XP Investimentos | B121: Mapfre Confianza XP Seg FIC FIF RF RL | C121: 56.385.272/0001-01 | D121: MAPFRE INVESTIMENTOS LTDA. | E121: 04.160.039/0001-27 | F121: BNY Mellon DTVM | G121: Renda Fixa | H121: Crédito Liquidez | I121: 100 | J121: 0.45 | M121: 0 | N121: 0 | Q121: Não | R121: Site (navegador) | S121: 1 | T121: Não | U121: Sim | V121: Não
A122: XP Investimentos | B122: Miles Virtus Advisory XP Seg Prev FIC FIA | C122: 34.475.121/0001-01 | D122: Miles Capital | F122: BNY Mellon DTVM | G122: Ações | H122: Renda Variável Long Only | I122: 100 | J122: 2 | M122: 2 | N122: 2 | Q122: Sim | R122: Site (navegador) | S122: 1 | T122: Não | U122: Sim | V122: Não
A123: XP Investimentos | B123: Moat Prev XP Seg FICFIA | C123: 37.037.432/0001-87 | D123: MOAT CAPITAL GESTÃO DE RECURSOS LTDA | E123: 18.730.786/0001-68 | F123: Intrag DTVM | G123: Ações | H123: Renda Variável Long Only | I123: 100 | J123: 2 | M123: 15 | N123: 2 | Q123: Não | R123: Site (navegador) | S123: 1 | T123: Não | U123: Sim | V123: Não
A124: XP Investimentos | B124: Neo Navitas Prev XP Seg FICFIA | C124: 41.081.187/0001-82 | D124: NEO Investimentos | F124: Intrag DTVM | G124: Ações | H124: Renda Variável Long Only | I124: 100 | J124: 2 | M124: 22 | N124: 2 | Q124: Sim | R124: Site (navegador) | S124: 1 | T124: Não | U124: Sim | V124: Não
A125: XP Investimentos | B125: Novus Bolsa Macro Global Prev Xp Seg Ficfia | C125: 38.035.023/0001-04 | D125: NOVUS CAPITAL GESTORA DE RECURSOS LTDA. | E125: 15.388.425/0001-97 | F125: Intrag DTVM | G125: Ações | H125: Renda Variável Long Biased | I125: 100 | J125: 2 | M125: 21 | N125: 2 | Q125: Sim | R125: Site (navegador) | S125: 1 | T125: Não | U125: Sim | V125: Não
...

Sheet BTG Pactual
A1: Plataforma | B1: Fundo | C1: CNPJ | D1: Gestora | E1: CNPJ da gestora | F1: Administrador | G1: Classe | H1: Categoria na origem | I1: Aplicação mínima (R$) | J1: Taxa adm (%) | K1: Taxa perf (%) | L1: Benchmark | M1: Cotização resgate (D+) | N1: Líquidação resgate (D+) | O1: Carência (dias) | P1: Tributação | Q1: Fechado p/ captação | R1: Fontes | S1: Nº de fontes | T1: Open Finance | U1: Prateleira (site) | V1: Área logada | W1: Link
A2: BTG Pactual | B2: 3R Genus Hedge Prev FIM RL | C2: 51.694.298/0001-18 | D2: 3R GESTORA DE RECURSOS LTDA | E2: 13.641.353/0001-12 | F2: BTG PACTUAL SERVICOS FINANCEIROS S.A. DISTRIBUIDOR | G2: Multimercado | H2: Renda Variável | I2: 1000 | K2: 20 | L2: - | M2: 3 | N2: 4 | P2: Curto Prazo | Q2: Sim | R2: API interna | S2: 1 | T2: Não | U2: Sim | V2: Não
A3: BTG Pactual | B3: A1 High Grade FIE I Prev BP FIC FIRF | C3: 67.124.600/0001-32 | D3: ASSET1 INVESTIMENTOS S/A | E3: 35.185.577/0001-08 | F3: BTG PACTUAL SERVICOS FINANCEIROS S.A. DISTRIBUIDOR | G3: Renda Fixa | H3: Outros | I3: 1000 | J3: 0.85 | M3: 0 | N3: 2 | P3: Longo Prazo | Q3: Não | R3: API interna | S3: 1 | T3: Não | U3: Sim | V3: Não
A4: BTG Pactual | B4: A1 RF Ativa Prev FICFIRF RL | C4: 60.356.190/0001-06 | D4: ASSET1 INVESTIMENTOS S/A | E4: 35.185.577/0001-08 | F4: BTG PACTUAL SERVICOS FINANCEIROS S.A. DISTRIBUIDOR | G4: Renda Fixa | H4: Renda Fixa | I4: 1000 | K4: 20 | L4: - | M4: 0 | N4: 1 | P4: Curto Prazo | Q4: Não | R4: API interna | S4: 1 | T4: Não | U4: Sim | V4: Não
A5: BTG Pactual | B5: ACE Capital Prev Icatu FICFIM RL | C5: 48.212.959/0001-17 | D5: ACE CAPITAL GESTORA DE RECURSOS LTDA. | E5: 33.411.393/0001-85 | F5: INTRAG DISTR DE TITULOS EVALORES MOBILIARIOS LTDA | G5: Multimercado | H5: Multimercado | I5: 1500 | J5: 2 | K5: 20 | L5: CDI | M5: 6 | N5: 7 | P5: Longo Prazo | Q5: Não | R5: API interna | S5: 1 | T5: Não | U5: Sim | V5: Não
A6: BTG Pactual | B6: ARX Denali Prev FIRF Access CrPr RL | C6: 47.564.808/0001-65 | D6: BTG PACTUAL GESTÃO E CONSULTORIA DE INVESTIMENTOS LTDA | E6: 12.695.840/0001-03 | F6: BTG PACTUAL SERVICOS FINANCEIROS S.A. DISTRIBUIDOR | G6: Renda Fixa | H6: Renda Fixa | I6: 1000 | M6: 2 | N6: 4 | P6: Curto Prazo | Q6: Não | R6: API interna | S6: 1 | T6: Não | U6: Sim | V6: Não
A7: BTG Pactual | B7: ARX Income Icatu Prev 100 FICFIA RL | C7: 37.355.672/0001-20 | D7: ARX INVESTIMENTOS LTDA | E7: 04.408.128/0001-40 | F7: BNY MELLON SERVICOS FINANCEIROS DTVM S/A | G7: Ações | H7: Renda Variável | I7: 5000 | J7: 2 | K7: 20 | L7: IBOVESPA | M7: 6 | N7: 8 | P7: Renda Variável | Q7: Não | R7: API interna | S7: 1 | T7: Não | U7: Sim | V7: Não
A8: BTG Pactual | B8: ARX Income Icatu Prev FIM RL | C8: 03.879.361/0001-48 | D8: ARX INVESTIMENTOS LTDA | E8: 04.408.128/0001-40 | F8: BNY MELLON SERVICOS FINANCEIROS DTVM S/A | G8: Multimercado | H8: Renda Variável | I8: 1000 | J8: 1.9 | M8: 1 | N8: 2 | P8: Não Aplicável | Q8: Não | R8: API interna | S8: 1 | T8: Não | U8: Sim | V8: Não
A9: BTG Pactual | B9: ARX K2 Prev FICFIM CrPr RL | C9: 33.165.244/0001-83 | D9: ARX INVESTIMENTOS LTDA | E9: 04.408.128/0001-40 | F9: BTG PACTUAL SERVICOS FINANCEIROS S.A. DISTRIBUIDOR | G9: Multimercado | H9: Renda Fixa | I9: 0 | J9: 1.1 | M9: 5 | N9: 7 | P9: Curto Prazo | Q9: Não | R9: API interna | S9: 1 | T9: Não | U9: Sim | V9: Não
A10: BTG Pactual | B10: ASA Hedge Icatu Prev FICFIM RL | C10: 26.343.792/0001-90 | D10: ASA ASSET MANAGEMENT LTDA. | E10: 19.807.960/0001-96 | F10: S3 CACEIS BRASIL DISTRIBUIDORA DE TITULOS E VALORE | G10: Multimercado | H10: Multimercado | I10: 1000 | J10: 0.95 | M10: 0 | N10: 3 | P10: Longo Prazo | Q10: Não | R10: API interna | S10: 1 | T10: Não | U10: Sim | V10: Não
A11: BTG Pactual | B11: AZ Quest Altro Prev FICFIM FIE Access CrPr RL | C11: 47.640.749/0001-67 | D11: BTG PACTUAL GESTÃO E CONSULTORIA DE INVESTIMENTOS LTDA | E11: 12.695.840/0001-03 | F11: BTG PACTUAL SERVICOS FINANCEIROS S.A. DISTRIBUIDOR | G11: Multimercado | H11: Renda Fixa | I11: 1000 | M11: 20 | N11: 21 | P11: Curto Prazo | Q11: Não | R11: API interna | S11: 1 | T11: Não | U11: Sim | V11: Não
A12: BTG Pactual | B12: AZ Quest Icatu Multi Prev FICFIM RL | C12: 18.534.967/0001-19 | D12: AZ Quest Prev Ltda. | E12: 59.312.965/0001-62 | F12: BNY MELLON SERVICOS FINANCEIROS DTVM S/A | G12: Multimercado | H12: Multimercado | I12: 1500 | J12: 2 | M12: 1 | N12: 3 | P12: Não Aplicável | Q12: Não | R12: API interna | S12: 1 | T12: Não | U12: Sim | V12: Não
A13: BTG Pactual | B13: AZ Quest Inflacao Ativo Prev FIE I FICFIRF RL | C13: 34.442.059/0001-51 | D13: AZ Quest Prev Ltda. | E13: 59.312.965/0001-62 | F13: BNY MELLON SERVICOS FINANCEIROS DTVM S/A | G13: Renda Fixa | H13: Renda Fixa | I13: 1500 | J13: 0.55 | M13: 0 | N13: 1 | P13: Longo Prazo | Q13: Não | R13: API interna | S13: 1 | T13: Não | U13: Sim | V13: Não
A14: BTG Pactual | B14: AZ Quest Prev Icatu Luce FICFIRF CrPr RL | C14: 23.883.385/0001-88 | D14: AZ Quest Prev Ltda. | E14: 59.312.965/0001-62 | F14: BNY MELLON SERVICOS FINANCEIROS DTVM S/A | G14: Renda Fixa | H14: Renda Fixa | I14: 3000 | J14: 0.55 | M14: 1 | N14: 3 | P14: Longo Prazo | Q14: Não | R14: API interna | S14: 1 | T14: Não | U14: Sim | V14: Não
A15: BTG Pactual | B15: Absolute Atenas Prev FIM Access CrPr RL | C15: 47.564.734/0001-67 | D15: BTG PACTUAL GESTÃO E CONSULTORIA DE INVESTIMENTOS LTDA | E15: 12.695.840/0001-03 | F15: BTG PACTUAL SERVICOS FINANCEIROS S.A. DISTRIBUIDOR | G15: Renda Fixa | H15: Renda Fixa | I15: 1000 | J15: 0.98 | M15: 6 | N15: 8 | P15: Curto Prazo | Q15: Não | R15: API interna | S15: 1 | T15: Não | U15: Sim | V15: Não
A16: BTG Pactual | B16: Absolute Delfos Prev FICFIRF Access CrPr RL | C16: 57.370.727/0001-88 | D16: BTG PACTUAL GESTÃO E CONSULTORIA DE INVESTIMENTOS LTDA | E16: 12.695.840/0001-03 | F16: BTG PACTUAL SERVICOS FINANCEIROS S.A. DISTRIBUIDOR | G16: Renda Fixa | H16: Renda Fixa | I16: 1000 | J16: 0.88 | M16: 20 | N16: 22 | P16: Curto Prazo | Q16: Não | R16: API interna | S16: 1 | T16: Não | U16: Sim | V16: Não
A17: BTG Pactual | B17: Absolute Hedge Prev FICFIM Access RL | C17: 61.861.454/0001-41 | D17: BTG PACTUAL GESTÃO E CONSULTORIA DE INVESTIMENTOS LTDA | E17: 12.695.840/0001-03 | F17: BTG PACTUAL SERVICOS FINANCEIROS S.A. DISTRIBUIDOR | G17: Multimercado | H17: Multimercado | I17: 1000 | J17: 2 | K17: 20 | L17: - | M17: 4 | N17: 5 | P17: Curto Prazo | Q17: Não | R17: API interna | S17: 1 | T17: Não | U17: Sim | V17: Não
A18: BTG Pactual | B18: Absolute Icatu I Prev FICFIM RL | C18: 29.242.441/0001-81 | D18: ABSOLUTE GESTAO DE INVESTIMENTOS LTDA | E18: 17.285.755/0001-82 | F18: BNY MELLON SERVICOS FINANCEIROS DTVM S/A | G18: Multimercado | H18: Multimercado | I18: 1500 | J18: 2 | K18: 20 | L18: CDI | M18: 0 | N18: 3 | P18: Longo Prazo | Q18: Não | R18: API interna | S18: 1 | T18: Não | U18: Sim | V18: Não
A19: BTG Pactual | B19: Absolute Pace Prev FICFIA Access RL | C19: 55.498.621/0001-39 | D19: BTG PACTUAL GESTÃO E CONSULTORIA DE INVESTIMENTOS LTDA | E19: 12.695.840/0001-03 | F19: BTG PACTUAL SERVICOS FINANCEIROS S.A. DISTRIBUIDOR | G19: Ações | H19: Renda Variável | I19: 0 | J19: 2 | K19: 20 | L19: - | M19: 22 | N19: 24 | P19: Curto Prazo | Q19: Sim | R19: API interna | S19: 1 | T19: Não | U19: Sim | V19: Não
A20: BTG Pactual | B20: Absolute Vertex Prev FIM Access RL | C20: 43.509.130/0001-67 | D20: BTG PACTUAL GESTÃO E CONSULTORIA DE INVESTIMENTOS LTDA | E20: 12.695.840/0001-03 | F20: BTG PACTUAL SERVICOS FINANCEIROS S.A. DISTRIBUIDOR | G20: Multimercado | H20: Multimercado | I20: 1000 | J20: 2 | K20: 20 | L20: CDI | M20: 21 | N20: 22 | P20: Curto Prazo | Q20: Não | R20: API interna | S20: 1 | T20: Não | U20: Sim | V20: Não
A21: BTG Pactual | B21: Adam BP Prev FICFIM RL | C21: 24.751.504/0001-01 | D21: ADAMCAPITAL GESTÃO DE RECURSOS LTDA. | E21: 17.905.206/0001-63 | F21: INTRAG DISTR DE TITULOS EVALORES MOBILIARIOS LTDA | G21: Multimercado | H21: Multimercado | I21: 1000 | J21: 2 | M21: 0 | N21: 2 | P21: Longo Prazo | Q21: Sim | R21: API interna | S21: 1 | T21: Não | U21: Sim | V21: Não
A22: BTG Pactual | B22: Adam Icatu RF Ativa Prev FICFIRF LP RL | C22: 52.091.995/0001-47 | D22: ADAMCAPITAL GESTÃO DE RECURSOS LTDA. | E22: 17.905.206/0001-63 | F22: INTRAG DISTR DE TITULOS EVALORES MOBILIARIOS LTDA | G22: Renda Fixa | H22: Renda Fixa | I22: 1500 | J22: 0.9 | M22: 5 | N22: 6 | P22: Longo Prazo | Q22: Não | R22: API interna | S22: 1 | T22: Não | U22: Sim | V22: Não
A23: BTG Pactual | B23: Alaska Long Only Prev 70 FICFIM RL | C23: 41.881.132/0001-57 | D23: ALASKA INVESTIMENTOS LTDA. | E23: 11.752.203/0001-50 | F23: BTG PACTUAL SERVICOS FINANCEIROS S.A. DISTRIBUIDOR | G23: Multimercado | H23: Renda Variável | I23: 1000 | J23: 1.65 | K23: 20 | L23: - | M23: 6 | N23: 8 | P23: Curto Prazo | Q23: Não | R23: API interna | S23: 1 | T23: Não | U23: Sim | V23: Não
A24: BTG Pactual | B24: Alaska Prev 100 Long Only FICFIM RL | C24: 37.313.900/0001-07 | D24: ALASKA INVESTIMENTOS LTDA. | E24: 11.752.203/0001-50 | F24: BTG PACTUAL SERVICOS FINANCEIROS S.A. DISTRIBUIDOR | G24: Multimercado | H24: Renda Variável | I24: 0 | J24: 1.5 | K24: 20 | L24: - | M24: 6 | N24: 8 | P24: Curto Prazo | Q24: Não | R24: API interna | S24: 1 | T24: Não | U24: Sim | V24: Não
A25: BTG Pactual | B25: Alphakey Prev 70 FIC FIF MM | C25: 65.655.653/0001-54 | D25: ALPHAKEY CAPITAL MANAGEMENT INVESTIMENTOS LTDA | E25: 31.340.246/0001-36 | F25: BTG PACTUAL SERVICOS FINANCEIROS S.A. DISTRIBUIDOR | G25: Multimercado | H25: Renda Variável | I25: 1000 | K25: 20 | L25: - | M25: 8 | N25: 10 | P25: Curto Prazo | Q25: Não | R25: API interna | S25: 1 | T25: Não | U25: Sim | V25: Não
A26: BTG Pactual | B26: Arca Grao Prev FICFIM Access RL | C26: 42.848.021/0001-01 | D26: GRÃO GESTÃO DE RECURSOS LTDA. | E26: 43.739.164/0001-48 | F26: S3 CACEIS BRASIL DISTRIBUIDORA DE TITULOS E VALORE | G26: Multimercado | H26: Alocação | I26: 1000 | J26: 0.59 | M26: 7 | N26: 9 | P26: Longo Prazo | Q26: Não | R26: API interna | S26: 1 | T26: Não | U26: Sim | V26: Não
A27: BTG Pactual | B27: Arca Grao Prev FICFIRF Access CrPr RL | C27: 57.445.402/0001-17 | D27: GRÃO GESTÃO DE RECURSOS LTDA. | E27: 43.739.164/0001-48 | F27: S3 CACEIS BRASIL DISTRIBUIDORA DE TITULOS E VALORE | G27: Renda Fixa | H27: Renda Fixa | I27: 1000 | J27: 0.59 | M27: 7 | N27: 9 | P27: Não Aplicável | Q27: Sim | R27: API interna | S27: 1 | T27: Não | U27: Sim | V27: Não
A28: BTG Pactual | B28: Armor Prev FIE I FIF MM | C28: 64.157.228/0001-72 | D28: ARMOR GESTORA DE RECURSOS LTDA. | E28: 34.176.302/0001-37 | F28: BTG PACTUAL SERVICOS FINANCEIROS S.A. DISTRIBUIDOR | G28: Multimercado | H28: Outros | I28: 1000 | K28: 20 | L28: - | M28: 5 | N28: 6 | P28: Longo Prazo | Q28: Não | R28: API interna | S28: 1 | T28: Não | U28: Sim | V28: Não
A29: BTG Pactual | B29: Artesanal Prev FIM RL | C29: 53.497.497/0001-61 | D29: ARTESANAL INVESTIMENTOS LTDA | E29: 03.084.098/0001-09 | F29: BTG PACTUAL SERVICOS FINANCEIROS S.A. DISTRIBUIDOR | G29: Multimercado | H29: Multimercado | I29: 100 | K29: 15 | L29: - | M29: 9 | N29: 10 | P29: Longo Prazo | Q29: Não | R29: API interna | S29: 1 | T29: Não | U29: Sim | V29: Não
A30: BTG Pactual | B30: Artica Prev FIM RL | C30: 54.347.632/0001-55 | D30: ARTICA GESTÃO DE RECURSOS LTDA | E30: 31.227.292/0001-23 | F30: BTG PACTUAL SERVICOS FINANCEIROS S.A. DISTRIBUIDOR | G30: Multimercado | H30: Renda Variável | I30: 1000 | K30: 20 | L30: IBOVESPA | M30: 88 | N30: 90 | P30: Curto Prazo | Q30: Não | R30: API interna | S30: 1 | T30: Não | U30: Sim | V30: Não
A31: BTG Pactual | B31: Atena Prev FICFIRF FIE 1 CrPr RL | C31: 53.798.822/0001-26 | D31: ATENA CAPITAL GESTÃO DE RECURSOS LTDA. | E31: 19.005.052/0001-89 | F31: BTG PACTUAL SERVICOS FINANCEIROS S.A. DISTRIBUIDOR | G31: Renda Fixa | H31: Renda Fixa | I31: 1000 | K31: 15 | L31: - | M31: 7 | N31: 9 | P31: Curto Prazo | Q31: Não | R31: API interna | S31: 1 | T31: Não | U31: Sim | V31: Não
A32: BTG Pactual | B32: Atlas ONE Icatu 70 Prev FIM RL | C32: 33.520.932/0001-14 | D32: ATLAS ONE INVESTIMENTOS GESTÃO DE RECURSOS LTDA. | E32: 36.658.682/0001-71 | F32: BEM DISTRIBUIDORA DE TITULOS E VALORES MOBILIARIOS | G32: Multimercado | H32: Renda Variável | I32: 1500 | J32: 0.55 | M32: 7 | N32: 9 | P32: Longo Prazo | Q32: Não | R32: API interna | S32: 1 | T32: Não | U32: Sim | V32: Não
A33: BTG Pactual | B33: BTG Alocacao Global Cred Prev FIM CrPr RL | C33: 52.279.451/0001-03 | D33: BTG PACTUAL ASSET MANAGEMENT S/A DTVM | E33: 29.650.082/0001-00 | F33: BTG PACTUAL SERVICOS FINANCEIROS S.A. DISTRIBUIDOR | G33: Multimercado | H33: Multimercado | I33: 1000 | M33: 7 | N33: 8 | P33: Curto Prazo | Q33: Não | R33: API interna | S33: 1 | T33: Não | U33: Sim | V33: Não
A34: BTG Pactual | B34: BTG Autoinvest Balanceado Prev FIM CrPr RL | C34: 44.672.908/0001-17 | D34: BTG PACTUAL GESTÃO E CONSULTORIA DE INVESTIMENTOS LTDA | E34: 12.695.840/0001-03 | F34: BTG PACTUAL SERVICOS FINANCEIROS S.A. DISTRIBUIDOR | G34: Multimercado | H34: Alocação | I34: 1000 | J34: 0.5 | K34: 10 | L34: CDI | M34: 7 | N34: 9 | P34: Curto Prazo | Q34: Não | R34: API interna | S34: 1 | T34: Não | U34: Sim | V34: Não
A35: BTG Pactual | B35: BTG Autoinvest Sofisticado Prev FIM CrPr RL | C35: 20.332.753/0001-01 | D35: BTG PACTUAL GESTÃO E CONSULTORIA DE INVESTIMENTOS LTDA | E35: 12.695.840/0001-03 | F35: BTG PACTUAL SERVICOS FINANCEIROS S.A. DISTRIBUIDOR | G35: Multimercado | H35: Alocação | I35: 1000 | J35: 1 | M35: 0 | N35: 2 | P35: Curto Prazo | Q35: Não | R35: API interna | S35: 1 | T35: Não | U35: Sim | V35: Não
A36: BTG Pactual | B36: BTG CDB Plus Prev FIM CrPr RL | C36: 47.564.915/0001-93 | D36: BTG PACTUAL ASSET MANAGEMENT S/A DTVM | E36: 29.650.082/0001-00 | F36: BTG PACTUAL SERVICOS FINANCEIROS S.A. DISTRIBUIDOR | G36: Multimercado | H36: Renda Fixa | I36: 1000 | M36: 0 | N36: 1 | P36: Curto Prazo | Q36: Não | R36: API interna | S36: 1 | T36: Não | U36: Sim | V36: Não
A37: BTG Pactual | B37: BTG Cred Corp OAK3 Global Prev FIE FIM CrPr RL | C37: 54.304.610/0001-08 | D37: BTG PACTUAL ASSET MANAGEMENT S/A DTVM | E37: 29.650.082/0001-00 | F37: BTG PACTUAL SERVICOS FINANCEIROS S.A. DISTRIBUIDOR | G37: Multimercado | H37: Renda Fixa | I37: 1000 | M37: 9 | N37: 12 | P37: Curto Prazo | Q37: Não | R37: API interna | S37: 1 | T37: Não | U37: Sim | V37: Não
A38: BTG Pactual | B38: BTG Icatu Vanguarda Absoluto II FIRF Prev CrPr RL | C38: 46.700.364/0001-85 | D38: ICATU VANGUARDA GESTÃO DE RECURSOS LTDA | E38: 68.622.174/0001-20 | F38: BEM DISTRIBUIDORA DE TITULOS E VALORES MOBILIARIOS | G38: Renda Fixa | H38: Renda Fixa | I38: 1000 | J38: 0.8 | K38: 20 | L38: CDI | M38: 9 | N38: 10 | P38: Longo Prazo | Q38: Não | R38: API interna | S38: 1 | T38: Não | U38: Sim | V38: Não
A39: BTG Pactual | B39: BTG Long Term Prev FIA FIE | C39: 57.976.621/0001-22 | D39: BTG PACTUAL ASSET MANAGEMENT S/A DTVM | E39: 29.650.082/0001-00 | F39: BTG PACTUAL SERVICOS FINANCEIROS S.A. DISTRIBUIDOR | G39: Ações | H39: Renda Variável | I39: 1000 | K39: 20 | L39: - | M39: 30 | N39: 32 | P39: Curto Prazo | Q39: Não | R39: API interna | S39: 1 | T39: Não | U39: Sim | V39: Não
A40: BTG Pactual | B40: BTG Multigestor Credit Plus Prev FICFIM CrPr RL | C40: 60.230.790/0001-23 | D40: BTG PACTUAL GESTÃO E CONSULTORIA DE INVESTIMENTOS LTDA | E40: 12.695.840/0001-03 | F40: BTG PACTUAL SERVICOS FINANCEIROS S.A. DISTRIBUIDOR | G40: Multimercado | H40: Renda Fixa | I40: 1000 | M40: 30 | N40: 32 | P40: Curto Prazo | Q40: Não | R40: API interna | S40: 1 | T40: Não | U40: Sim | V40: Não
...

Sheet Itaú Private
A1: Plataforma | B1: Fundo | C1: CNPJ | D1: Gestora | E1: CNPJ da gestora | F1: Administrador | G1: Classe | H1: Categoria na origem | I1: Aplicação mínima (R$) | J1: Taxa adm (%) | K1: Taxa perf (%) | L1: Benchmark | M1: Cotização resgate (D+) | N1: Líquidação resgate (D+) | O1: Carência (dias) | P1: Tributação | Q1: Fechado p/ captação | R1: Fontes | S1: Nº de fontes | T1: Open Finance | U1: Prateleira (site) | V1: Área logada | W1: Link
A2: Itaú Private | B2: Canvas Enduro Prev PVT MM | D2: CANVAS CAPITAL S.A. | G2: Multimercado | H2: Multimercados | J2: 2 | Q2: Não | R2: Site (HTML) | S2: 1 | T2: Não | U2: Sim | V2: Não
